Workbook
Name C_C: parameters!$H$3
Name cycle_length: parameters!$H$51
Name fracinfected: parameters!#REF!
Name U_I: parameters!$H$96
Name U_S: parameters!$H$87

Sheet Readme

Sheet Inputs Table >>

Sheet parameters
B1: Category | C1: Parameter | D1: Definition | E1: Currency | F1: Year | G1: Value | H1: Lower | I1: Upper | J1: Distribution | K1: Source | L1: Comments
D2: General
B3: Cohort | C3: n_cohort | D3: Cohort size | E3: NA | F3: NA | G3: 1000 | H3: NA | I3: NA | J3: NA | K3: Assumption
B4: Time | C4: cycle_length_days | D4: Cycle length, days | E4: NA | F4: NA | G4: 7 | H4: NA | I4: NA | J4: NA | K4: Assumption
B5: Time | C5: time_horizon_years | D5: Analytic time horizon, years | E5: NA | F5: NA | G5: 10 | H5: 1 | I5: 20 | J5: NA | K5: Assumption
B6: Simulations | C6: n_boot_samps | D6: Number of bootstrap samples | E6: NA | F6: NA | G6: 1000 | H6: NA | I6: NA | J6: NA | K6: Assumption
B7: Demographics | C7: Mean_age | D7: Mean age of working age population, 15-64 years | E7: NA | F7: NA | G7: 38 | H7: 15 | I7: 64 | J7: Gamma | K7: https://agenciadenoticias.ibge.gov.br/en/agencia-news/2184-news-agency/news/38187-2022-census-number-of-elderly-persons-in-the-brazilian-population-grew-57-4-in-12-years
B8: Epidemic | D8: Epidemic Parameters
B9: Epidemic | C9: total_inf_cases | D9: Total cases | E9: NA | F9: NA | G9: 425773 | H9: =_xlfn.CHISQ.INV(0.025,2*G9)/2 -> 424495.05 | I9: =_xlfn.CHISQ.INV(0.975,2*(G9-1))/2 -> 427051.85 | J9: Chi-square | K9: Health Information Platform of the Americas (PLISA). Data reported by the Ministries and Institutes of Health of the countries and territories of the Region: https://www.paho.org/en/arbo-portal/chikungunya-data-and-analysis/chikungunya-analysis-country | L9: Rates are per 100,000 populations
B10: Epidemic | C10: base_population | D10: Implied population | E10: NA | F10: NA | G10: =G9/(200.84/100000) -> 2.1199612e+08 | H10: NA | I10: NA | J10: NA | K10: Health Information Platform of the Americas (PLISA). Data reported by the Ministries and Institutes of Health of the countries and territories of the Region: https://www.paho.org/en/arbo-portal/chikungunya-data-and-analysis/chikungunya-analysis-country | L10: Rates are per 100,000 populations
B11: Epidemic | C11: R0 | D11: Basic reproduction number | E11: NA | F11: NA | G11: 3.4 | H11: 2.4 | I11: 4.2 | J11: Gamma | K11: Haider et al, 2020
B12: Epidemic | C12: xi | D12: Behavioural response factor | E12: NA | F12: NA | G12: 1 | H12: =G12*(1-0.05) -> 0.95 | I12: =G12*(1+0.05) -> 1.05 | J12: PERT | K12: Assumption
B13: Epidemic | C13: lambda_days | D13: Incubation period, days | E13: NA | F13: NA | G13: 5 | H13: 1 | I13: 12 | J13: Gamma | K13: https://www.cdc.gov/yellow-book/hcp/travel-associated-infections-diseases/chikungunya.html | L13: Assuming incubation period is 5 days so 0.2 per day
B14: Epidemic | C14: gamma_days | D14: Average duration of infection, days | E14: NA | F14: NA | G14: 8.5 | H14: 7 | I14: 10 | J14: Gamma | K14: https://www.cdc.gov/yellow-book/hcp/travel-associated-infections-diseases/chikungunya.html | L14: Assumes recovery in 7-10 days, 8.5 days as midpoint.
B15: Epidemic | C15: rho_year | D15: Proportion of patients with CCA after 12 months of infection | E15: NA | F15: NA | G15: 0.521 | H15: 0.445 | I15: 0.597 | J15: Gamma | K15: Bertolotti et al, 2020
B16: Epidemic | C16: prop_hosp | D16: Proportion of patients hospitalized | E16: NA | F16: NA | G16: 0.018 | H16: =(1-0.25)*G16 -> 0.0135 | I16: =(1+0.25)*G16 -> 0.0225 | J16: Beta | K16: de Andrade, et al. 2022 | L16: de Andrade quotes 1.8% hospitalization. Gonçalves quotes 0.67% (256/38830)
B17: Epidemic | C17: delta_hosp_10years | D17: CHIKV case-fatality rate, hospitalized patients | E17: NA | F17: NA | G17: =(84+1)/(7337+84+2) -> 0.011450896 | H17: =_xlfn.BETA.INV(0.025, 84+1, 7337+84-84+1) -> 0.0091577628 | I17: =_xlfn.BETA.INV(0.975, 84+1, 7337+84-84+1) -> 0.013993176 | J17: Beta | K17: Pedi et al. 2025 | L17: Total column in Table 3: https://pmc.ncbi.nlm.nih.gov/articles/PMC12407205/pdf/25-0554.pdf
B18: Epidemic | C18: deaths_CHIKV_pop | D18: CHIKV deaths, general population, 2017 | E18: NA | F18: NA | G18: 250 | H18: =_xlfn.CHISQ.INV(0.025,2*G18)/2 -> 219.968 | I18: =_xlfn.CHISQ.INV(0.975,2*(G18-1))/2 -> 280.8637 | J18: Chi-square | K18: Vidal et al. 2021 | L18: https://onlinelibrary.wiley.com/doi/10.1111/tmi.13711
B19: Epidemic | C19: CHIKV_pop | D19: Implied population | E19: NA | F19: NA | G19: =+G18*100000/1.2 -> 20833333 | H19: NA | I19: NA | J19: NA | K19: Vidal et al. 2021 | L19: https://onlinelibrary.wiley.com/doi/10.1111/tmi.13711
B20: Epidemic | C20: seroresponse_placebo_IXCHIQ_180_days | D20: Vaccine efficacy rate for placebo group at 180 days, IXCHIQ | E20: NA | F20: NA | G20: 0 | H20: 0 | I20: 0.053 | J20: Beta | K20: Schneider et al, 2023 | L20: 18-64 years; 180 days after vaccination (Supplementary Table 3)
B21: Epidemic | C21: seroresponse_treatment_IXCHIQ_180_days | D21: Vaccine efficacy rate for treatment group at 180 days, IXCHIQ | E21: NA | F21: NA | G21: 0.984 | H21: 0.953 | I21: 0.997 | J21: Beta | K21: Schneider et al, 2023 | L21: 18-64 years; 180 days after vaccination (Supplementary Table 3)
B22: Epidemic | C22: seroprotection_VIMKUNYA_183_days | D22: Vaccine efficacy rate at 183 days, VIMKUNYA | E22: NA | F22: NA | G22: 0.84 | H22: 0.817 | I22: 0.856 | J22: Beta | K22: Richardson et al., 2025 | L22: seroresponse, Table 2
B23: Epidemic | C23: zeta | D23: Immunogenicity atenuation factor | E23: NA | F23: NA | G23: 0.8 | H23: 0.7 | I23: 1 | J23: NA | K23: Assumption
B24: Epidemic | C24: prop_severe_vse_IXCHIQ | D24: Proportion of severe adverse events IXCHIQ | E24: NA | F24: NA | G24: =58/3082 -> 0.018818949 | H24: =_xlfn.BETA.INV(0.025, 58, 3082-58+1) -> 0.014320248 | I24: =_xlfn.BETA.INV(0.975, 58+1, 3082-58) -> 0.024260663 | J24: Beta | K24: Schneider M et a., 2023 | L24: Confidence intervals are two-sided exact Clopper–Pearson 95% confidence intervals.
B25: Epidemic | C25: prop_severe_vse_VIMKUNYA | D25: Proportion of severe adverse events VIMKUNYA | E25: NA | F25: NA | G25: =73/2790 -> 0.026164875 | H25: =_xlfn.BETA.INV(0.025, 73, 2790-73+1) -> 0.020563875 | I25: =_xlfn.BETA.INV(0.975, 73+1, 2790-73) -> 0.032787184 | J25: Beta | K25: Richardson et al., 2025 | L25: Greater or equal grade 3 (Table 3); Confidence intervals are two-sided exact Clopper–Pearson 95% confidence intervals.
B26: Epidemic | C26: prop_serious_vse_IXCHIQ | D26: Proportion of serious adverse events IXCHIQ | E26: NA | F26: NA | G26: =2/3082 -> 0.00064892927 | H26: =_xlfn.BETA.INV(0.025, 2, 3082-2+1) -> 7.8598009e-05 | I26: =_xlfn.BETA.INV(0.975, 2+1, 3082-2) -> 0.0023421695 | J26: Beta | K26: Schneider M et a., 2023 | L26: Only two serious adverse events were considered related to VLA1553 treatment (one mild myalgia and one syndrome of inappropriate antidiuretic hormone secretion). Both participants recovered fully.
B27: Epidemic | C27: prop_serious_vse_VIMKUNYA | D27: Proportion of serious adverse events VIMKUNYA | E27: NA | F27: NA | G27: =(23-1)/2790 -> 0.0078853047 | H27: =_xlfn.BETA.INV(0.025, 23-1, 2790-(23-1)+1) -> 0.0049480848 | I27: =_xlfn.BETA.INV(0.975, 73+1, 2790-73) -> 0.032787184 | J27: Beta | K27: Richardson et al., 2025 | L27: Confidence intervals are two-sided exact Clopper–Pearson 95% confidence intervals.
B28: Epidemic | C28: psi_stated | D28: 3-weeks vaccination rate | E28: NA | F28: NA | G28: 0.55 | H28: 0.51 | I28: 0.7 | J28: PERT | K28: Assumption | L28: Manaquin R, Desmoulin A, Luong Nguyen LB, et al. Acceptance of chikungunya vaccination: a rapid survey in Reunion island during an epidemic. Vaccine. 2025/10/03/ 2025;64:127720. doi:https://doi.org/10.1016/j.vaccine.2025.127720 40. World Health Organization. Chikungunya - La Réunion and Mayotte. WHO. December 11, 2025. Updated May 12, 2025. Accessed December 11, 2025. https://www.who.int/emergencies/disease-outbreak-news/item/2025-DON567 41. Curren EJ, Ellis EM, Hennessey MJ, Delorey MJ, Fischer M, Staples JE. Acceptability of a Chikungunya Virus Vaccine, United States Virgin Islands. Am J Trop Med Hyg. Feb 1 2023;108(2):363-365. doi:10.4269/ajtmh.22-0429 42. Quenard F, Pecout F, Barry TA, et al. Acceptability of a chikungunya vaccine and dengue vaccine among travelers in Martinique (French West Indies), for the travel and for their home territory. IJID Reg. Dec 2025;17:100791. doi:10.1016/j.ijregi.2025.100791
B29: Epidemic | C29: phi | D29: Realization factor for vaccination | E29: NA | F29: NA | G29: 0.6 | H29: 0.4 | I29: 0.75 | J29: PERT | K29: Assumption
B30: Epidemic | C30: omicron | D30: IXCHQ preference weight | E30: NA | F30: NA | G30: 1 | H30: 0.5 | I30: 1.5 | J30: PERT | K30: Assumption
B31: Epidemic | C31: pi_VIMKUNYA_vs_IXCHIQ | D31: VIMKUNYA preference weight, relative to IXCHIQ | E31: NA | F31: NA | G31: 1 | H31: 0.5 | I31: 1.2 | J31: PERT | K31: Assumption
B32: Epidemic | C32: theta_IXCHIQ_days | D32: Vaccine daily waning rate, IXCHIQ | E32: NA | F32: NA | G32: 2.640161e-05 | H32: 0 | I32: 6.943443e-05 | J32: Lognormal | K32: Calculated from McMahon, R., Toepfer, S., Sattler, N., et al. Antibody persistence and safety of a live-attenuated chikungunya virus vaccine up to 2 years after single-dose administration in adults in the USA: a single-arm, multicentre, phase 3b study. Lancet Infectious Diseases. 2024;24(12):1383–1392. | L32: See Appendix
B33: Epidemic | C33: theta_VIMKUNYA_days | D33: Vaccine daily waning rate, VIMKUNYA | E33: NA | F33: NA | G33: 0.0008298682 | H33: 0.0006795308 | I33: 0.0009955332 | J33: Lognormal | K33: Calculated from Richardson et al. | L33: See Appendix
B34: Epidemic | C34: kappa_days | D34: Average duration of chronic disease, days | E34: NA | F34: NA | G34: 365 | H34: =(1/3)*G34 -> 121.66667 | I34: =2*G34 -> 730 | J34: Gamma | K34: Paixao 2018 | L34: Assume patients recover from the chronic form of disease in 12 months
B35: Utilities | D35: Utilities
B36: Utilities | C36: qol_S | D36: Susceptible | E36: NA | F36: NA | G36: 0.824 | H36: =G36 - _xlfn.T.INV.2T(0.05, 5774-1) * (0.172 / SQRT(5774)) -> 0.81956259 | I36: =G36 + _xlfn.T.INV.2T(0.05, 5774-1) * (0.172 / SQRT(5774)) -> 0.82843741 | J36: Beta | K36: Santos M, et al. 2021; Table 3
B37: Utilities | C37: qol_D | D37: Death | E37: NA | F37: NA | G37: 0 | H37: NA | I37: NA | J37: NA | K37: Assumption
B38: Utilities | C38: df_dw | D38: Devere dengue fever disability weight | E38: NA | F38: NA | G38: =gbd_2023_healthstate_appendix_t!D197 -> 0.13341152 | H38: =gbd_2023_healthstate_appendix_t!E197 -> 0.088459515 | I38: =gbd_2023_healthstate_appendix_t!F197 -> 0.18950167 | J38: Beta | K38: Global Burden of Disease Collaborative Network. Global Burden of Disease Study 2023 (GBD 2023) Disability Weights. Seattle, United States of America: Institute for Health Metrics and Evaluation (IHME), 2025.
B39: Utilities | C39: qol_E_factor | D39: Exposed (latent) utility multiplier | E39: NA | F39: NA | G39: =0.85 -> 0.85 | H39: =MAX((1-0.25)*G39, 0) -> 0.6375 | I39: =MIN(1, (1+0.25)*G39) -> 1 | J39: Beta | K39: Assumption
B40: Utilities | C40: qol_C_factor | D40: Chronic Disease (persistent polyarthritis) utility multiplier | E40: NA | F40: NA | G40: =0.6 -> 0.6 | H40: =G40-((0.19)/SQRT(315))*_xlfn.T.INV.2T(0.05, 315-1) -> 0.57893684 | I40: =G40+((0.19)/SQRT(315))*_xlfn.T.INV.2T(0.05, 315-1) -> 0.62106316 | J40: Beta | K40: Linde L, et al. 2013 | L40: SD = 0.19, assuming utility Rheumatoid Arthritis = utility in chronic phase; N = 315
...

Sheet gbd_2023_healthstate_appendix_t
A1: sequela_name | B1: healthstate_name | C1: healthstate_description | D1: mean | E1: lower | F1: upper
A2: HIV/AIDS - Drug-susceptible Tuberculosis without anemia | B2: Tuberculosis, HIV infected | C2: has a persistent cough and fever, shortness of breath, night sweats, weakness and fatigue and severe weight loss. | D2: 0.4084592 | E2: 0.27357894 | F2: 0.5494645
A3: HIV/AIDS - Drug-susceptible Tuberculosis with mild anemia | B3: Tuberculosis, HIV infected and anemia, mild | C3: (combined DW) | D3: 0.41069636 | E3: 0.27806277 | F3: 0.55068574
A4: HIV/AIDS - Drug-susceptible Tuberculosis with moderate anemia | B4: Tuberculosis, HIV infected and anemia, moderate | C4: (combined DW) | D4: 0.43866321 | E4: 0.30654567 | F4: 0.57724937
A5: HIV/AIDS - Drug-susceptible Tuberculosis with severe anemia | B5: Tuberculosis, HIV infected and anemia, severe | C5: (combined DW) | D5: 0.494827 | E5: 0.35294457 | F5: 0.64020241
A6: HIV/AIDS - Multidrug-resistant Tuberculosis without extensive drug resistance without anemia | B6: Tuberculosis, HIV infected | C6: has a persistent cough and fever, shortness of breath, night sweats, weakness and fatigue and severe weight loss. | D6: 0.4084592 | E6: 0.27357894 | F6: 0.5494645
A7: HIV/AIDS - Multidrug-resistant Tuberculosis without extensive drug resistance with mild anemia | B7: Tuberculosis, HIV infected and anemia, mild | C7: (combined DW) | D7: 0.41069636 | E7: 0.27806277 | F7: 0.55068574
A8: HIV/AIDS - Multidrug-resistant Tuberculosis without extensive drug resistance with moderate anemia | B8: Tuberculosis, HIV infected and anemia, moderate | C8: (combined DW) | D8: 0.43866321 | E8: 0.30654567 | F8: 0.57724937
A9: HIV/AIDS - Multidrug-resistant Tuberculosis without extensive drug resistance with severe anemia | B9: Tuberculosis, HIV infected and anemia, severe | C9: (combined DW) | D9: 0.494827 | E9: 0.35294457 | F9: 0.64020241
A10: HIV/AIDS - Extensively drug-resistant Tuberculosis without anemia | B10: Tuberculosis, HIV infected | C10: has a persistent cough and fever, shortness of breath, night sweats, weakness and fatigue and severe weight loss. | D10: 0.4084592 | E10: 0.27357894 | F10: 0.5494645
A11: HIV/AIDS - Extensively drug-resistant Tuberculosis with mild anemia | B11: Tuberculosis, HIV infected and anemia, mild | C11: (combined DW) | D11: 0.41069636 | E11: 0.27806277 | F11: 0.55068574
A12: HIV/AIDS - Extensively drug-resistant Tuberculosis with moderate anemia | B12: Tuberculosis, HIV infected and anemia, moderate | C12: (combined DW) | D12: 0.43866321 | E12: 0.30654567 | F12: 0.57724937
A13: HIV/AIDS - Extensively drug-resistant Tuberculosis with severe anemia | B13: Tuberculosis, HIV infected and anemia, severe | C13: (combined DW) | D13: 0.494827 | E13: 0.35294457 | F13: 0.64020241
... A16: Early HIV without anemia | B16: Generic uncomplicated disease: anxiety about diagnosis | C16: has a disease diagnosis that causes some worry but minimal interference with daily activities. | D16: 0.012440831 | E16: 0.0061947475 | F16: 0.022708942
A17: Early HIV with mild anemia | B17: Anemia, mild; Generic uncomplicated disease anxiety | D17: 0.016083331 | E17: 0.007595395 | F17: 0.030998713
A18: Early HIV with moderate anemia | B18: Anemia, moderate; Generic uncomplicated disease anxiety | D18: 0.063305862 | E18: 0.039980345 | F18: 0.094802634
A19: Early HIV with severe anemia | B19: Anemia, severe; Generic uncomplicated disease anxiety | D19: 0.15932515 | E19: 0.10850395 | F19: 0.22044928
A20: Symptomatic HIV with mild anemia | B20: HIV cases, symptomatic, pre-AIDS and anemia, mild | C20: (combined DW) | D20: 0.27718122 | E20: 0.1885033 | F20: 0.37914755
A21: Symptomatic HIV with moderate anemia | B21: HIV cases, symptomatic, pre-AIDS and anemia, moderate | C21: (combined DW) | D21: 0.31158532 | E21: 0.21665629 | F21: 0.41803402
A22: Symptomatic HIV with severe anemia | B22: HIV cases, symptomatic, pre-AIDS and anemia, severe | C22: (combined DW) | D22: 0.38114762 | E22: 0.26857991 | F22: 0.50458203
A23: AIDS with mild anemia | B23: AIDS cases, not receiving ARV treatment and anemia, mild | C23: (combined DW) | D23: 0.58321627 | E23: 0.40917474 | F23: 0.74297647
A24: AIDS with moderate anemia | B24: AIDS cases, not receiving ARV treatment and anemia, moderate | C24: (combined DW) | D24: 0.60291261 | E24: 0.43024704 | F24: 0.75831274
A25: AIDS with severe anemia | B25: AIDS cases, not receiving ARV treatment and anemia, severe | C25: (combined DW) | D25: 0.64201905 | E25: 0.47004963 | F25: 0.79216009
A26: HIV/AIDS with antiretroviral treatment without anemia | B26: HIV/AIDS cases, receiving ARV treatment | C26: has occasional fevers and infections. The person takes daily medication that sometimes causes diarrhea. | D26: 0.078017329 | E26: 0.05212429 | F26: 0.11106666
A27: HIV/AIDS with antiretroviral treatment with mild anemia | B27: HIV/AIDS cases, receiving ARV treatment and anemia, mild | C27: (combined DW) | D27: 0.081413316 | E27: 0.054154643 | F27: 0.11574106
A28: HIV/AIDS with antiretroviral treatment with moderate anemia | B28: HIV/AIDS cases, receiving ARV treatment and anemia, moderate | C28: (combined DW) | D28: 0.12539264 | E28: 0.084764614 | F28: 0.1764145
A29: HIV/AIDS with antiretroviral treatment with severe anemia | B29: HIV/AIDS cases, receiving ARV treatment and anemia, severe | C29: (combined DW) | D29: 0.21481863 | E29: 0.14811106 | F29: 0.29504815
A30: Asymptomatic congenital syphilis | B30: Asymptomatic | D30: 0 | E30: 0 | F30: 0
A31: Early symptomatic congenital syphilis, infectious syndrome | B31: Infectious disease, acute episode, moderate | C31: has a fever and aches, and feels weak, which causes some difficulty with daily activities. | D31: 0.050594946 | E31: 0.032378222 | F31: 0.07405045
A32: Late symptomatic congenital syphilis, neurosyphilis | B32: Motor plus cognitive impairments, moderate | C32: has some difficulty in moving around, holding objects, dressing and sitting upright, but can walk without help. The person has low intelligence and is slow in learning to speak and to do simple tasks. | D32: 0.20294601 | E32: 0.13394816 | F32: 0.28958335
A33: Early symptomatic congenital syphilis, slight disfigurement | B33: Disfigurement, level 1 | C33: has a slight, visible physical deformity that others notice, which causes some worry and discomfort. | D33: 0.011016252 | E33: 0.0052397625 | F33: 0.020619542
A34: Late symptomatic congenital syphilis, slight disfigurement | B34: Disfigurement, level 1 | C34: has a slight, visible physical deformity that others notice, which causes some worry and discomfort. | D34: 0.011016252 | E34: 0.0052397625 | F34: 0.020619542
A35: Late symptomatic congenital syphilis, unilateral hearing loss | B35: Hearing loss, unilateral | C35: can hear well with one ear but has hearing loss in the other ear, resulting in some trouble following a conversation in a noisy environment | D35: 0.0079861649 | E35: 0.00359251 | F35: 0.015490782
A36: Asymptomatic early syphilis infection | B36: Asymptomatic | D36: 0 | E36: 0 | F36: 0
A37: Mild early syphilis infection | B37: Infectious disease, acute episode, mild | C37: has a low fever and mild discomfort , but no difficulty with daily activities. | D37: 0.0057864972 | E37: 0.00229985 | F37: 0.012109072
A38: Asymptomatic adult tertiary syphilis | B38: Asymptomatic | D38: 0 | E38: 0 | F38: 0
A39: Cardiovascular complications due to adult tertiary syphilis | B39: Infectious disease, acute episode, moderate | C39: has a fever and aches, and feels weak, which causes some difficulty with daily activities. | D39: 0.050594946 | E39: 0.032378222 | F39: 0.07405045
A40: Severe disfigurement due to adult tertiary syphilis | B40: Disfigurement, level 3 | C40: has an obvious physical deformity that makes others uncomfortable, which causes the person to avoid social contact, feel worried, sleep poorly, and think about suicide. | D40: 0.40479054 | E40: 0.27450638 | F40: 0.54553343
A41: Neurological problems due to adult tertiary syphilis | B41: Motor plus cognitive impairments, moderate | C41: has some difficulty in moving around, holding objects, dressing and sitting upright, but can walk without help. The person has low intelligence and is slow in learning to speak and to do simple tasks. | D41: 0.20294601 | E41: 0.13394816 | F41: 0.28958335
A42: Neurological problems and cardiovascular complications due to adult tertiary syphilis | B42: Moderate motor plus cognitive impairments and moderate infectious disease, acute episode | C42: (combined DW) | D42: 0.24302715 | E42: 0.16800283 | F42: 0.33310622
...

Sheet Vaccine Efficacy >>

Sheet seroresponse
A1: measure | B1: days | C1: value | D1: lower | E1: upper | F1: vaccine | G1: source | H1: comments
A2: Seroprotection | B2: 29 | C2: 0.989 | D2: 0.967 | E2: 0.998 | F2: IXCHIQ | G2: Schneider et al. Lancet. 2023 | H2: Overall, Table 2
A3: Seroprotection | B3: 29 | C3: 0.991 | D3: 0.975 | E3: 0.998 | F3: IXCHIQ | G3: McMahon et al. Lancet ID. 2024 | H3: Overall; Figure 2
A4: Seroprotection | B4: =6*30.44 -> 182.64 | C4: 0.978 | D4: 0.956 | E4: 0.99 | F4: IXCHIQ | G4: McMahon et al. Lancet ID. 2024 | H4: Overall; Figure 2
A5: Seroprotection | B5: 365 | C5: 0.989 | D5: 0.972 | E5: 0.997 | F5: IXCHIQ | G5: McMahon et al. Lancet ID. 2024 | H5: Overall; Figure 2
A6: Seroprotection | B6: =+B5*2 -> 730 | C6: 0.968 | D6: 0.943 | E6: 0.985 | F6: IXCHIQ | G6: McMahon et al. Lancet ID. 2024 | H6: Overall; Figure 2
A7: Seroresponse rate differences | B7: 8 | C7: 0.461 | D7: 0.438 | E7: 0.481 | F7: VIMKUNYA | G7: Richardson JS, Anderson DM, Mendy J, Tindale LC, Muhammad S, Loreth T, Tredo SR, Warfield KL, Ramanathan R, Caso JT, Jenkins VA, Ajiboye P, Bedell L; EBSI-CV-317-004 Study Group. Chikungunya virus virus-like particle vaccine safety and immunogenicity in adolescents and adults in the USA: a phase 3, randomised, double-blind, placebo-controlled trial. Lancet. 2025 Apr 19;405(10487):1343-1352. doi: 10.1016/S0140-6736(25)00345-9. Epub 2025 Mar 27. PMID: 40158526. | H7: Table 2
A8: Seroresponse rate differences | B8: 15 | C8: 0.96 | D8: 0.943 | E8: 0.968 | F8: VIMKUNYA | G8: Richardson JS, Anderson DM, Mendy J, Tindale LC, Muhammad S, Loreth T, Tredo SR, Warfield KL, Ramanathan R, Caso JT, Jenkins VA, Ajiboye P, Bedell L; EBSI-CV-317-004 Study Group. Chikungunya virus virus-like particle vaccine safety and immunogenicity in adolescents and adults in the USA: a phase 3, randomised, double-blind, placebo-controlled trial. Lancet. 2025 Apr 19;405(10487):1343-1352. doi: 10.1016/S0140-6736(25)00345-9. Epub 2025 Mar 27. PMID: 40158526. | H8: Table 2
A9: Seroresponse rate differences | B9: 22 | C9: 0.966 | D9: 0.95 | E9: 0.975 | F9: VIMKUNYA | G9: Richardson JS, Anderson DM, Mendy J, Tindale LC, Muhammad S, Loreth T, Tredo SR, Warfield KL, Ramanathan R, Caso JT, Jenkins VA, Ajiboye P, Bedell L; EBSI-CV-317-004 Study Group. Chikungunya virus virus-like particle vaccine safety and immunogenicity in adolescents and adults in the USA: a phase 3, randomised, double-blind, placebo-controlled trial. Lancet. 2025 Apr 19;405(10487):1343-1352. doi: 10.1016/S0140-6736(25)00345-9. Epub 2025 Mar 27. PMID: 40158526. | H9: Table 2
A10: Seroresponse rate differences | B10: 183 | C10: 0.84 | D10: 0.817 | E10: 0.856 | F10: VIMKUNYA | G10: Richardson JS, Anderson DM, Mendy J, Tindale LC, Muhammad S, Loreth T, Tredo SR, Warfield KL, Ramanathan R, Caso JT, Jenkins VA, Ajiboye P, Bedell L; EBSI-CV-317-004 Study Group. Chikungunya virus virus-like particle vaccine safety and immunogenicity in adolescents and adults in the USA: a phase 3, randomised, double-blind, placebo-controlled trial. Lancet. 2025 Apr 19;405(10487):1343-1352. doi: 10.1016/S0140-6736(25)00345-9. Epub 2025 Mar 27. PMID: 40158526. | H10: Table 2

Sheet Demographics >>

Sheet life_tables
A2: BRASIL: Tábua Completa de Mortalidade - Ambos os Sexos – 2024
G3: (Continua)
A4: Idades | B4: Probabilidades de Morte | C4: Óbitos | D4: l ( X ) | E4: L (X, N) | F4: T(X) | G4: Expectativa de Vida
A5: Exatas | B5: entre Duas Idades Exatas | C5: D (X, N) | G5: à Idade X
A6: (X) | B6: Q (X, N) (Por Mil) | G6: E(X)
A7: age | B7: death_prob | G7: life_expectancy
A8: 0 | B8: 12.255129 | C8: 1225.5129 | D8: 100000 | E8: 98926.551 | F8: 7660788.4 | G8: 76.607884
A9: 1 | B9: 0.74460443 | C9: 73.547921 | D9: 98774.487 | E9: 98737.713 | F9: 7561861.8 | G9: 76.556832
A10: 2 | B10: 0.59254521 | C10: 58.484769 | D10: 98700.939 | E10: 98671.697 | F10: 7463124.1 | G10: 75.613506
A11: 3 | B11: 0.47361227 | C11: 46.718277 | D11: 98642.454 | E11: 98619.095 | F11: 7364452.4 | G11: 74.658041
A12: 4 | B12: 0.38209617 | C12: 37.673054 | D12: 98595.736 | E12: 98576.9 | F12: 7265833.3 | G12: 73.69318
A13: 5 | B13: 0.31305262 | C13: 30.853859 | D13: 98558.063 | E13: 98542.636 | F13: 7167256.4 | G13: 72.721157
A14: 6 | B14: 0.26253592 | C14: 25.866932 | D14: 98527.209 | E14: 98514.276 | F14: 7068713.8 | G14: 71.743773
A15: 7 | B15: 0.22730591 | C15: 22.389937 | D15: 98501.342 | E15: 98490.147 | F15: 6970199.5 | G15: 70.762482
A16: 8 | B16: 0.20513093 | C16: 20.201079 | D16: 98478.952 | E16: 98468.852 | F16: 6871709.4 | G16: 69.778457
A17: 9 | B17: 0.19482619 | C17: 19.182343 | D17: 98458.751 | E17: 98449.16 | F17: 6773240.5 | G17: 68.792671
A18: 10 | B18: 0.19662671 | C18: 19.355848 | D18: 98439.569 | E18: 98429.891 | F18: 6674791.3 | G18: 67.805979
A19: 11 | B19: 0.21238234 | C19: 20.902715 | D19: 98420.213 | E19: 98409.762 | F19: 6576361.5 | G19: 66.819216
... A97: 89 | B97: 128.8042 | C97: 3097.6415 | D97: 24049.227 | E97: 22500.407 | F97: 128385.23 | G97: 5.3384347
A98: 90 ou mais | B98: 1000 | C98: 20951.586 | D98: 20951.586 | E98: 105884.82 | F98: 105884.82 | G98: 5.0537856
A99: Fonte: IBGE, Diretoria de Pesquisas (DPE), Coordenação de População e Indicadores Sociais (COPIS).
A101: Notas:
A102: N = 1
A103: Q(X, N) = Probabilidades de morte entre as idades exatas X e X+N.
A104: l(X) = Número de sobreviventes à idade exata X.
A105: D(X, N) = Número de óbitos ocorridos entre as idades X e X+N.
A106: L(X, N) = Número de pessoas-anos vividos entre as idades X e X+N.
A107: T(X) = Número de pessoas-anos vividos a partir da idade X.
A108: E(X) = Expectativa de vida à idade X.

Sheet age_pyramid
A1: Age | B1: M | C1: F
A2: 0-4 | B2: 6682042 | C2: 6413556
A3: 45786 | B3: 7241538 | C3: 6953921
A4: 45944 | B4: 7342997 | C4: 7055760
A5: 15-19 | B5: 7575432 | C5: 7301316
A6: 20-24 | B6: 7970234 | C6: 7760334
A7: 25-29 | B7: 8241074 | C7: 8130717
A8: 30-34 | B8: 8048069 | C8: 8031559
A9: 35-39 | B9: 8293365 | C9: 8382279
A10: 40-44 | B10: 8156539 | C10: 8366021
A11: 45-49 | B11: 7272748 | C11: 7582165
A12: 50-54 | B12: 6366856 | C12: 6747807
A13: 55-59 | B13: 5724442 | C13: 6194348
A14: 60-64 | B14: 5084846 | C14: 5654490
A15: 65-69 | B15: 3993485 | C15: 4640221
A16: 70-74 | B16: 2877264 | C16: 3565249
... A22: 100+ | B22: 2629 | C22: 4986

Sheet Costs >>

Sheet tax_rates
A1: lower_taxable_income | B1: upper_taxable_income | C1: tax_rate | D1: parcela | E1: Source
A2: 0 | B2: 26963.2 | C2: 0 | D2: 0 | E2: https://www.gov.br/receitafederal/pt-br/assuntos/meu-imposto-de-renda/tabelas/copy_of_2024
A3: 26963.21 | B3: 33919.8 | C3: 0.075 | D3: 2022.24 | E3: https://www.gov.br/receitafederal/pt-br/assuntos/meu-imposto-de-renda/tabelas/copy_of_2024
A4: 33919.81 | B4: 45012.6 | C4: 0.15 | D4: 4566.23 | E4: https://www.gov.br/receitafederal/pt-br/assuntos/meu-imposto-de-renda/tabelas/copy_of_2024
A5: 45012.61 | B5: 55976.16 | C5: 0.225 | D5: 7942.17 | E5: https://www.gov.br/receitafederal/pt-br/assuntos/meu-imposto-de-renda/tabelas/copy_of_2024
A6: 55976.17 | B6: Inf | C6: 0.275 | D6: 10740.98 | E6: https://www.gov.br/receitafederal/pt-br/assuntos/meu-imposto-de-renda/tabelas/copy_of_2024

Sheet qdenga_price
B1: QDENGA ICER BY CONITEC - BRAZILIAN AGENCY
B4: Source: National Commission for the Incorporation of Technologies in the Unified Health System. (2023). Recommendation report No. 871: Tetravalent dengue vaccine (attenuated) for the prevention of infection caused by the dengue virus and its complications. Ministry of Health.
B6: PMVG without taxes | C6: PMVG 0% (R$) | D6: PMVG 18% (R$) | E6: Suggested price by Takeda for SUS (R$) | F6: Final price agreement (R$) | H6: Gap between final price and initial max price
B7: 157.35 | C7: 176.23 | D7: 220.83 | E7: 170 | F7: 95 | G7: =+F7/D7 -> 0.43019517 | H7: =1-G7 -> 0.56980483

Sheet pneumo-13_price
B7: PNEUMO-13 VACCINE
C12: PMVG 0% (R$) | D12: Suggested price by Pfizer for SUS (R$)
C13: 131.92 | D13: 63.85
G15: Although the vaccine had already been incorporated in 2019 for high-risk groups,
G16: it was in this 2023 report (attempt to substitute PCV10 with PCV13 for all children) that the offered price became explicit and significantly below the market price, consolidating the argument for government negotiation.
B27: Discount Aggressiveness: The Pfizzer offered the vaccine for R$ 63.85, which represents a discount of about 51%compared to the CMED ceiling price (R$ 131.92).
B28: Comparison with Current Prices: The offered value (R$ 63.85) was even lower than the price the government was already paying for the same vaccine for high-risk groups (CRIE), which was R$ 76.50.
B30: Disclosures
B31: Why was it not incorporated even with the discount? Despite the attractive price, Conitec recommended against incorporation based on three main pillars:
B33: 1.Hidden Logistics Costs: PCV13 is supplied in a pre-filled syringe (larger volume), while the current vaccine (PCV10) is a multidose vial. The change would generate an extra cost for logistics and storage (cold chain) estimated at more than R$ 16 million per year, which would "offset" part of the savings from the dose price.
B35: 2. Industrial Policy: The current vaccine (PCV10) is produced by Fiocruz (national) via technology transfer, ensuring self-sufficiency for the country.
B37: 3. Epidemiological Data: The Ministry of Health assessed that there was no epidemiological emergency justifying the switch, as severe cases remained stable.
B41: Source: National Commission for the Incorporation of Technologies in the Unified Health System. (2023).
B42: Recommendation report No. 819: 13-valent pneumococcal conjugate vaccine for immunization of children up to five years of age against invasive pneumococcal disease and pneumonia. Ministry of Health
B43: https://www.gov.br/conitec/pt-br/midias/relatorios/2023/20230710_relatorio_vacinapcv13_pneumo.pdf

Sheet chiqx_price
B1: CHICUNGUNYA BRAZIL LEGAL PRICE
B3: Source: CMED (https://www.gov.br/anvisa/pt-br/assuntos/medicamentos/cmed/precos)
B5: ICMS % (tax)* | C5: PMVG (Max Gov Price, R$) | D5: PMC (Max Consumer Price, R$) | E5: PMVG (USD) | F5: PMC (USD)
B6: 0 | C6: 761.88 | D6: 1022.03 | E6: =C6/5.66 -> 134.60777 | F6: =D6/5.66 -> 180.57067
B7: 0.12 | C7: 865.77 | D7: 1161.4 | E7: =C7/5.66 -> 152.9629 | F7: =D7/5.66 -> 205.19435 | I7: BRL | J7: BRL
B8: 0.17 | C8: 917.93 | D8: 1231.37 | E8: =C8/5.66 -> 162.17845 | F8: =D8/5.66 -> 217.55654 | I8: Public | J8: Private | M8: Base | N8: LB | O8: UB
B9: 0.175 | C9: 923.49 | D9: 1238.83 | E9: =C9/5.66 -> 163.16078 | F9: =D9/5.66 -> 218.87456 | H9: LB | I9: =+C6 -> 761.88 | J9: =+D6 -> 1022.03 | L9: Public | M9: =I10 -> 929.12 | N9: =I9 -> 761.88 | O9: =I11 -> 989.45
B10: 0.18 | C10: 929.12 | D10: 1246.38 | E10: =C10/5.66 -> 164.15548 | F10: =D10/5.66 -> 220.20848 | H10: Base | I10: =+C10 -> 929.12 | J10: =+D10 -> 1246.38 | L10: Private | M10: =J10 -> 1246.38 | N10: =J9 -> 1022.03 | O10: =J11 -> 1327.31
B11: 0.19 | C11: 940.59 | D11: 1261.77 | E11: =C11/5.66 -> 166.18198 | F11: =D11/5.66 -> 222.92756 | H11: UB | I11: =+C18 -> 989.45 | J11: =+D18 -> 1327.31
B12: 0.195 | C12: 946.43 | D12: 1269.61 | E12: =C12/5.66 -> 167.21378 | F12: =D12/5.66 -> 224.31272
B13: 0.2 | C13: 952.35 | D13: 1277.54 | E13: =C13/5.66 -> 168.25972 | F13: =D13/5.66 -> 225.71378
B14: 0.205 | C14: 958.34 | D14: 1285.58 | E14: =C14/5.66 -> 169.31802 | F14: =D14/5.66 -> 227.13428
B15: 0.21 | C15: 964.41 | D15: 1293.72 | E15: =C15/5.66 -> 170.39046 | F15: =D15/5.66 -> 228.57244
B16: 0.22 | C16: 976.77 | D16: 1310.3 | E16: =C16/5.66 -> 172.5742 | F16: =D16/5.66 -> 231.50177
B17: 0.225 | C17: 983.07 | D17: 1318.75 | E17: =C17/5.66 -> 173.68728 | F17: =D17/5.66 -> 232.9947
B18: 0.23 | C18: 989.45 | D18: 1327.31 | E18: =C18/5.66 -> 174.81449 | F18: =D18/5.66 -> 234.50707
B20: * Depending on the region (State of Brazil), taxes can reach 23%.
B21: US = 5,66 REAIS
B23: Term Meaning
B24: PMVG Maximum Selling Price to the Government – ​​is the highest price at which a medicine can be sold to public bodies and entities. It is used as a reference in purchases by the SUS (Brazilian Public Health System), Ministry of Health, states and municipalities.
B26: PMC Maximum Price to the Consumer – is the price ceiling that private pharmacies and hospitals can charge the final consumer. It varies according to the ICMS (Brazilian state sales tax) of each state.
B28: The maximum price varies according to the taxes in each region. Taxes range from 0% to 23% and it has an impact on price. This is not the final price that can be used for incorporation into the Brazilian public health system.
B30: Using the price of the Qdenga vaccine as a proxy is interesting because it was the price incorporated into the public health system, which was well below that established by CMED.
B32: 18% is usually choose as a reference for CONITEC calculation for ICER analysis

Sheet calculations
B2: Vaccine | C2: Manufacturer | D2: Year | E2: Comments | F2: PMVG without taxes | G2: PMVG 0% (R$) | H2: PMVG 18% (R$) | I2: Manufacturer Price for SUS (R$) | J2: Final price agreement (R$) | K2: Price Discount
B3: QDENGA | C3: Takeda | D3: 2025 | E3: Planned for implementation | F3: =qdenga_price!B7 -> 157.35 | G3: =qdenga_price!C7 -> 176.23 | H3: =qdenga_price!D7 -> 220.83 | I3: =qdenga_price!E7 -> 170 | J3: =qdenga_price!F7 -> 95 | K3: =1-J3/H3 -> 0.56980483
B4: Pneumo13 | C4: Pfizer | D4: 2023 | E4: Not implemented | G4: ='pneumo-13_price'!$C$13 -> 131.92 | H4: =+(H3/G3)*G4 -> 165.3061 | I4: ='pneumo-13_price'!$D$13 -> 63.85 | J4: 76.75 | K4: =1-J4/H4 -> 0.53570981

Sheet Adjustments >>

Sheet cpi
A1: Variação acumulada no ano durante o Plano Real
B3: Year | C3: Brasil | D3: Cumulative
A4: 199512#dezembro 1995 | B4: 1995 | C4: 22.41
A5: 199612#dezembro 1996 | B5: =+B4+1 -> 1996 | C5: 9.56
A6: 199712#dezembro 1997 | B6: =+B5+1 -> 1997 | C6: 5.22
A7: 199812#dezembro 1998 | B7: =+B6+1 -> 1998 | C7: 1.65
A8: 199912#dezembro 1999 | B8: =+B7+1 -> 1999 | C8: 8.94
A9: 200012#dezembro 2000 | B9: =+B8+1 -> 2000 | C9: 5.97
A10: 200112#dezembro 2001 | B10: =+B9+1 -> 2001 | C10: 7.67
A11: 200212#dezembro 2002 | B11: =+B10+1 -> 2002 | C11: 12.53
A12: 200312#dezembro 2003 | B12: =+B11+1 -> 2003 | C12: 9.3
A13: 200412#dezembro 2004 | B13: =+B12+1 -> 2004 | C13: 7.6
A14: 200512#dezembro 2005 | B14: =+B13+1 -> 2005 | C14: 5.69
A15: 200612#dezembro 2006 | B15: =+B14+1 -> 2006 | C15: 3.14
A16: 200712#dezembro 2007 | B16: =+B15+1 -> 2007 | C16: 4.46
... A18: 200912#dezembro 2009 | B18: =+B17+1 -> 2009 | C18: 4.31
A19: 201012#dezembro 2010 | B19: =+B18+1 -> 2010 | C19: 5.91 | D19: =D18+C19/100 -> 0.0591
A20: 201112#dezembro 2011 | B20: =+B19+1 -> 2011 | C20: 6.5 | D20: =D19+C20/100 -> 0.1241
A21: 201212#dezembro 2012 | B21: =+B20+1 -> 2012 | C21: 5.84 | D21: =D20+C21/100 -> 0.1825
A22: 201312#dezembro 2013 | B22: =+B21+1 -> 2013 | C22: 5.91 | D22: =D21+C22/100 -> 0.2416
A23: 201412#dezembro 2014 | B23: =+B22+1 -> 2014 | C23: 6.41 | D23: =D22+C23/100 -> 0.3057
A24: 201512#dezembro 2015 | B24: =+B23+1 -> 2015 | C24: 10.67 | D24: =D23+C24/100 -> 0.4124
A25: 201612#dezembro 2016 | B25: =+B24+1 -> 2016 | C25: 6.29 | D25: =D24+C25/100 -> 0.4753
A26: 201712#dezembro 2017 | B26: =+B25+1 -> 2017 | C26: 2.95 | D26: =D25+C26/100 -> 0.5048
A27: 201812#dezembro 2018 | B27: =+B26+1 -> 2018 | C27: 3.75 | D27: =D26+C27/100 -> 0.5423
A28: 201912#dezembro 2019 | B28: =+B27+1 -> 2019 | C28: 4.31 | D28: =D27+C28/100 -> 0.5854
A29: 202012#dezembro 2020 | B29: =+B28+1 -> 2020 | C29: 4.52 | D29: =D28+C29/100 -> 0.6306
A30: 202112#dezembro 2021 | B30: =+B29+1 -> 2021 | C30: 10.06 | D30: =D29+C30/100 -> 0.7312
... A34: 202512#dezembro 2025 | B34: =+B33+1 -> 2025 | C34: 4.26 | D34: =D33+C34/100 -> 0.9262
A36: Fonte: "IBGE - Índice Nacional de Preços ao Consumidor Amplo"
A37: https://www.ibge.gov.br/en/statistics/economic/prices-and-costs/17136-national-consumer-pricce-index.html?lang=en-GB&t=series-historicas

Sheet cpi_old
A1: observation_date | B1: BRACPIALLMINMEI | E1: FRED Graph Observations
A2: 29190 | B2: 1.767538e-10 | E2: Federal Reserve Economic Data, Federal Reserve Bank of St. Louis
A3: 29221 | B3: 1.884472e-10 | E3: Link: https://fred.stlouisfed.org
A4: 29252 | B4: 1.971477e-10 | E4: Help: https://fredhelp.stlouisfed.org
A5: 29281 | B5: 2.090522e-10 | E5: This data may be copyrighted. Please refer to the Terms of Use: https://fred.stlouisfed.org/legal#fred-terms-faq
A6: 29312 | B6: 2.201029e-10 | E6: File Created: 2025-12-19 8:51 pm CST
A7: 29342 | B7: 2.326548e-10
A8: 29373 | B8: 2.449979e-10 | E8: BRACPIALLMINMEI | F8: Consumer Price Indices (CPIs, HICPs), COICOP 1999: Consumer Price Index: Total for Brazil, Index 2015=100, Monthly, Not Seasonally Adjusted | G8: Data Updated: 2025-05-15
A9: 29403 | B9: 2.585845e-10 | E9: https://fred.stlouisfed.org/series/BRACPIALLMINMEI
A10: 29434 | B10: 2.71373e-10
A11: 29465 | B11: 2.82853e-10
A12: 29495 | B12: 3.096689e-10
A13: 29526 | B13: 3.303343e-10
A14: 29556 | B14: 3.521828e-10
A15: 29587 | B15: 3.762634e-10
A16: 29618 | B16: 4.003486e-10
A17: 29646 | B17: 4.202529e-10
A18: 29677 | B18: 4.474099e-10
A19: 29707 | B19: 4.722839e-10
A20: 29738 | B20: 4.983435e-10
A21: 29768 | B21: 5.29519e-10
... A373: 40483 | B373: 73.68427
A374: 40513 | B374: 74.14853 | C374: =AVERAGE(B363:B374) -> 72.260279
A375: 40544 | B375: 74.76406
A376: 40575 | B376: 75.36218
A377: 40603 | B377: 75.95753
A378: 40634 | B378: 76.54243
A379: 40664 | B379: 76.90228
A380: 40695 | B380: 77.01759
A381: 40725 | B381: 77.14079
A382: 40756 | B382: 77.42616
A383: 40787 | B383: 77.83659
A384: 40817 | B384: 78.17139
A385: 40848 | B385: 78.57787
A386: 40878 | B386: 78.97067 | C386: =AVERAGE(B375:B386) -> 77.055795
A387: 40909 | B387: 79.41289
A388: 40940 | B388: 79.77019
A389: 40969 | B389: 79.9377
A390: 41000 | B390: 80.44929
A391: 41030 | B391: 80.73884
...

Sheet spot_fx_rate
A1: observation_date | B1: AEXBZUS
A2: 34700 | B2: 0.9161
A3: 35065 | B3: 1.0051
A4: 35431 | B4: 1.0779
A5: 35796 | B5: 1.1605
A6: 36161 | B6: 1.8207
A7: 36526 | B7: 1.8301
A8: 36892 | B8: 2.3527
A9: 37257 | B9: 2.9213
A10: 37622 | B10: 3.075
A11: 37987 | B11: 2.9262
A12: 38353 | B12: 2.4352
A13: 38718 | B13: 2.1738
... A32: 45658 | B32: 5.5891
A35: https://fred.stlouisfed.org/series/AEXBZUS
A36: FRED Graph Observations
A37: Federal Reserve Economic Data, Federal Reserve Bank of St. Louis
A38: Link: https://fred.stlouisfed.org
A39: Help: https://fredhelp.stlouisfed.org
A40: This data may be copyrighted. Please refer to the Terms of Use: https://fred.stlouisfed.org/legal#fred-terms-faq
A41: File Created: 2026-02-15 9:17 pm CST
A43: AEXBZUS | B43: Brazilian Reals to U.S. Dollar Spot Exchange Rate, Brazilian Reals to One U.S. Dollar, Annual, Not Seasonally Adjusted | C43: Data Updated: 2026-01-05
